<?xml version="1.0" encoding="UTF-8"?><testsuite name="nosetests" tests="6" errors="2" failures="1" skip="1"><testcase classname="&lt;unittest.result" name="TestResult run=1 errors=1 failures=0&gt;" time="0.000"><error type="builtins.TypeError" message="oops, wrong type"><![CDATA[Traceback (most recent call last):
  File "/Library/Frameworks/Python.framework/Versions/3.12/lib/python3.12/unittest/case.py", line 58, in testPartExecutor
    yield
  File "/Library/Frameworks/Python.framework/Versions/3.12/lib/python3.12/unittest/case.py", line 634, in run
    self._callTestMethod(testMethod)
  File "/Library/Frameworks/Python.framework/Versions/3.12/lib/python3.12/unittest/case.py", line 589, in _callTestMethod
    if method() is not None:
       ^^^^^^^^
  File "/Users/ats/Development/GitHub/nose-py3/functional_tests/support/xunit/test_xunit_as_suite.py", line 17, in test_error
    raise TypeError("oops, wrong type")
TypeError: oops, wrong type
]]></error></testcase><testcase classname="&lt;unittest.result" name="TestResult run=1 errors=0 failures=1&gt;" time="0.000"><failure type="builtins.AssertionError" message="'this' != 'that'&#10;- this&#10;+ that&#10;"><![CDATA[Traceback (most recent call last):
  File "/Library/Frameworks/Python.framework/Versions/3.12/lib/python3.12/unittest/case.py", line 58, in testPartExecutor
    yield
  File "/Library/Frameworks/Python.framework/Versions/3.12/lib/python3.12/unittest/case.py", line 634, in run
    self._callTestMethod(testMethod)
  File "/Library/Frameworks/Python.framework/Versions/3.12/lib/python3.12/unittest/case.py", line 589, in _callTestMethod
    if method() is not None:
       ^^^^^^^^
  File "/Users/ats/Development/GitHub/nose-py3/functional_tests/support/xunit/test_xunit_as_suite.py", line 14, in test_fail
    self.assertEqual("this", "that")
  File "/Library/Frameworks/Python.framework/Versions/3.12/lib/python3.12/unittest/case.py", line 885, in assertEqual
    assertion_func(first, second, msg=msg)
  File "/Library/Frameworks/Python.framework/Versions/3.12/lib/python3.12/unittest/case.py", line 1251, in assertMultiLineEqual
    self.fail(self._formatMessage(msg, standardMsg))
  File "/Library/Frameworks/Python.framework/Versions/3.12/lib/python3.12/unittest/case.py", line 715, in fail
    raise self.failureException(msg)
AssertionError: 'this' != 'that'
- this
+ that

]]></failure></testcase><testcase classname="&lt;unittest.result" name="TestResult run=1 errors=1 failures=0&gt;" time="0.000"><error type="builtins.Exception" message="日本"><![CDATA[Traceback (most recent call last):
  File "/Library/Frameworks/Python.framework/Versions/3.12/lib/python3.12/unittest/case.py", line 58, in testPartExecutor
    yield
  File "/Library/Frameworks/Python.framework/Versions/3.12/lib/python3.12/unittest/case.py", line 634, in run
    self._callTestMethod(testMethod)
  File "/Library/Frameworks/Python.framework/Versions/3.12/lib/python3.12/unittest/case.py", line 589, in _callTestMethod
    if method() is not None:
       ^^^^^^^^
  File "/Users/ats/Development/GitHub/nose-py3/functional_tests/support/xunit/test_xunit_as_suite.py", line 20, in test_non_ascii_error
    raise Exception(u"日本")
Exception: 日本
]]></error></testcase><testcase classname="&lt;unittest.result" name="TestResult run=1 errors=0 failures=0&gt;" time="0.000"><system-out><![CDATA[test-generated output
test-generated output
]]></system-out></testcase><testcase classname="&lt;unittest.result" name="TestResult run=1 errors=0 failures=0&gt;" time="0.000"><skipped type="unittest.case.SkipTest" message="skipit"><![CDATA[Exception: skipit
]]></skipped></testcase><testcase classname="&lt;unittest.result" name="TestResult run=1 errors=0 failures=0&gt;" time="0.000"></testcase></testsuite>